Traceback (most recent call last):
  File "D:\Users\lr826\AppData\Roaming\Python\Python312\site-packages\jupyter_cache\executors\utils.py", line 58, in single_nb_execution
    executenb(
  File "D:\Users\lr826\AppData\Roaming\Python\Python312\site-packages\nbclient\client.py", line 1314, in execute
    return NotebookClient(nb=nb, resources=resources, km=km, **kwargs).execute()
           ^^^^^^^^^^^^^^^^^^^^^^^^^^^^^^^^^^^^^^^^^^^^^^^^^^^^^^^^^^^^^^^^^^^^^
  File "D:\Users\lr826\AppData\Roaming\Python\Python312\site-packages\jupyter_core\utils\__init__.py", line 165, in wrapped
    return loop.run_until_complete(inner)
           ^^^^^^^^^^^^^^^^^^^^^^^^^^^^^^
  File "D:\Users\lr826\.conda\envs\gee\Lib\asyncio\base_events.py", line 687, in run_until_complete
    return future.result()
           ^^^^^^^^^^^^^^^
  File "D:\Users\lr826\AppData\Roaming\Python\Python312\site-packages\nbclient\client.py", line 709, in async_execute
    await self.async_execute_cell(
  File "D:\Users\lr826\AppData\Roaming\Python\Python312\site-packages\nbclient\client.py", line 1062, in async_execute_cell
    await self._check_raise_for_error(cell, cell_index, exec_reply)
  File "D:\Users\lr826\AppData\Roaming\Python\Python312\site-packages\nbclient\client.py", line 918, in _check_raise_for_error
    raise CellExecutionError.from_cell_and_msg(cell, exec_reply_content)
nbclient.exceptions.CellExecutionError: An error occurred while executing the following cell:
------------------
import numpy

# CreaciÃ³n del arreglo
arr = np.arange(1, 11)
------------------


[1;31m---------------------------------------------------------------------------[0m
[1;31mNameError[0m                                 Traceback (most recent call last)
Cell [1;32mIn[2], line 4[0m
[0;32m      1[0m [38;5;28;01mimport[39;00m [38;5;21;01mnumpy[39;00m
[0;32m      3[0m [38;5;66;03m# CreaciÃ³n del arreglo[39;00m
[1;32m----> 4[0m arr [38;5;241m=[39m [43mnp[49m[38;5;241m.[39marange([38;5;241m1[39m, [38;5;241m11[39m)

[1;31mNameError[0m: name 'np' is not defined

